<?xml version="1.0" ?>
<!-- =================================================================================== -->
<!-- |    This document was autogenerated by xacro from robot.urdf.xacro               | -->
<!-- |    EDITING THIS FILE BY HAND IS NOT RECOMMENDED                                 | -->
<!-- =================================================================================== -->
<robot name="indoor_mapping_robot">
  <!-- =====================================================
       ROBOT PHYSICAL PARAMETERS - VERIFIED FROM HARDWARE
       Based on actual measurements and test results
       ===================================================== -->
  <!-- ~15kg total -->
  <!-- ~500g per wheel -->
  <!-- Wheels below base -->
  <!-- 2cm radius -->
  <!-- 15cm up -->
  <!-- 5cm above base -->
  <!-- =====================================================
       VISUAL MATERIALS
       ===================================================== -->
  <material name="wood_brown">
    <color rgba="0.6 0.4 0.2 1.0"/>
  </material>
  <material name="metal_gray">
    <color rgba="0.5 0.5 0.5 1.0"/>
  </material>
  <material name="black_rubber">
    <color rgba="0.1 0.1 0.1 1.0"/>
  </material>
  <material name="blue_electronics">
    <color rgba="0.0 0.2 0.8 1.0"/>
  </material>
  <material name="red_lidar">
    <color rgba="1.0 0.0 0.0 1.0"/>
  </material>
  <material name="green_imu">
    <color rgba="0.0 0.8 0.2 1.0"/>
  </material>
  <!-- =====================================================
       BASE LINK (Robot Main Body)
       ===================================================== -->
  <link name="base_link">
    <visual>
      <geometry>
        <box size="0.4 0.5 0.3"/>
      </geometry>
      <material name="wood_brown"/>
      <origin rpy="0 0 0" xyz="0 0 0"/>
    </visual>
    <collision>
      <geometry>
        <box size="0.42000000000000004 0.52 0.3"/>
      </geometry>
      <origin rpy="0 0 0" xyz="0 0 0"/>
    </collision>
    <inertial>
      <mass value="15.0"/>
      <origin rpy="0 0 0" xyz="0 0 0"/>
      <inertia ixx="0.42499999999999993" ixy="0" ixz="0" iyy="0.3125" iyz="0" izz="0.5125000000000001"/>
    </inertial>
  </link>
  <!-- =====================================================
       WHEELS (2 Front Driven + 2 Rear Passive)
       Motor configuration: GPIO pins 17,18 (left) and 22,23 (right)
       ===================================================== -->
  <!-- Front Left Wheel (Driven - Motor pins 17,18) -->
  <link name="front_left_wheel">
    <visual>
      <geometry>
        <cylinder length="0.029" radius="0.072"/>
      </geometry>
      <material name="black_rubber"/>
      <origin rpy="1.5707963267948966 0 0" xyz="0 0 0"/>
    </visual>
    <collision>
      <geometry>
        <cylinder length="0.029" radius="0.072"/>
      </geometry>
      <origin rpy="1.5707963267948966 0 0" xyz="0 0 0"/>
    </collision>
    <inertial>
      <mass value="0.5"/>
      <origin rpy="0 0 0" xyz="0 0 0"/>
      <inertia ixx="0.0006830416666666665" ixy="0" ixz="0" iyy="0.0006830416666666665" iyz="0" izz="0.0012959999999999998"/>
    </inertial>
  </link>
  <joint name="front_left_wheel_joint" type="continuous">
    <parent link="base_link"/>
    <child link="front_left_wheel"/>
    <origin rpy="0 0 0" xyz="0.1 0.2286 -0.05"/>
    <axis xyz="0 1 0"/>
  </joint>
  <!-- Front Right Wheel (Driven - Motor pins 22,23) -->
  <link name="front_right_wheel">
    <visual>
      <geometry>
        <cylinder length="0.029" radius="0.072"/>
      </geometry>
      <material name="black_rubber"/>
      <origin rpy="1.5707963267948966 0 0" xyz="0 0 0"/>
    </visual>
    <collision>
      <geometry>
        <cylinder length="0.029" radius="0.072"/>
      </geometry>
      <origin rpy="1.5707963267948966 0 0" xyz="0 0 0"/>
    </collision>
    <inertial>
      <mass value="0.5"/>
      <origin rpy="0 0 0" xyz="0 0 0"/>
      <inertia ixx="0.0006830416666666665" ixy="0" ixz="0" iyy="0.0006830416666666665" iyz="0" izz="0.0012959999999999998"/>
    </inertial>
  </link>
  <joint name="front_right_wheel_joint" type="continuous">
    <parent link="base_link"/>
    <child link="front_right_wheel"/>
    <origin rpy="0 0 0" xyz="0.1 -0.2286 -0.05"/>
    <axis xyz="0 1 0"/>
  </joint>
  <!-- Rear Left Wheel (Passive Caster) -->
  <link name="rear_left_wheel">
    <visual>
      <geometry>
        <cylinder length="0.029" radius="0.072"/>
      </geometry>
      <material name="black_rubber"/>
      <origin rpy="1.5707963267948966 0 0" xyz="0 0 0"/>
    </visual>
    <collision>
      <geometry>
        <cylinder length="0.029" radius="0.072"/>
      </geometry>
      <origin rpy="1.5707963267948966 0 0" xyz="0 0 0"/>
    </collision>
    <inertial>
      <mass value="0.5"/>
      <origin rpy="0 0 0" xyz="0 0 0"/>
      <inertia ixx="0.0006830416666666665" ixy="0" ixz="0" iyy="0.0006830416666666665" iyz="0" izz="0.0012959999999999998"/>
    </inertial>
  </link>
  <joint name="rear_left_wheel_joint" type="continuous">
    <parent link="base_link"/>
    <child link="rear_left_wheel"/>
    <origin rpy="0 0 0" xyz="-0.1 0.2286 -0.05"/>
    <axis xyz="0 1 0"/>
  </joint>
  <!-- Rear Right Wheel (Passive Caster) -->
  <link name="rear_right_wheel">
    <visual>
      <geometry>
        <cylinder length="0.029" radius="0.072"/>
      </geometry>
      <material name="black_rubber"/>
      <origin rpy="1.5707963267948966 0 0" xyz="0 0 0"/>
    </visual>
    <collision>
      <geometry>
        <cylinder length="0.029" radius="0.072"/>
      </geometry>
      <origin rpy="1.5707963267948966 0 0" xyz="0 0 0"/>
    </collision>
    <inertial>
      <mass value="0.5"/>
      <origin rpy="0 0 0" xyz="0 0 0"/>
      <inertia ixx="0.0006830416666666665" ixy="0" ixz="0" iyy="0.0006830416666666665" iyz="0" izz="0.0012959999999999998"/>
    </inertial>
  </link>
  <joint name="rear_right_wheel_joint" type="continuous">
    <parent link="base_link"/>
    <child link="rear_right_wheel"/>
    <origin rpy="0 0 0" xyz="-0.1 -0.2286 -0.05"/>
    <axis xyz="0 1 0"/>
  </joint>
  <!-- =====================================================
       CAMERA POLE (4-foot painter's pole)
       ===================================================== -->
  <link name="camera_pole">
    <visual>
      <geometry>
        <cylinder length="1.219" radius="0.02"/>
      </geometry>
      <material name="metal_gray"/>
      <origin rpy="0 0 0" xyz="0 0 0.6095"/>
    </visual>
    <collision>
      <geometry>
        <cylinder length="1.219" radius="0.02"/>
      </geometry>
      <origin rpy="0 0 0" xyz="0 0 0.6095"/>
    </collision>
    <inertial>
      <mass value="2.0"/>
      <origin rpy="0 0 0" xyz="0 0 0.6095"/>
      <inertia ixx="0.24786016666666671" ixy="0" ixz="0" iyy="0.24786016666666671" iyz="0" izz="0.0004"/>
    </inertial>
  </link>
  <joint name="base_to_pole" type="fixed">
    <parent link="base_link"/>
    <child link="camera_pole"/>
    <origin rpy="0 0 0" xyz="0 0 0.15"/>
  </joint>
  <!-- =====================================================
       LIDAR SENSOR (RPLidar A1M8) - VERIFIED POSITION
       ===================================================== -->
  <link name="lidar_link">
    <visual>
      <geometry>
        <cylinder length="0.06" radius="0.035"/>
      </geometry>
      <material name="red_lidar"/>
      <origin rpy="0 0 0" xyz="0 0 0"/>
    </visual>
    <collision>
      <geometry>
        <cylinder length="0.06" radius="0.035"/>
      </geometry>
      <origin rpy="0 0 0" xyz="0 0 0"/>
    </collision>
    <inertial>
      <mass value="0.5"/>
      <origin rpy="0 0 0" xyz="0 0 0"/>
      <inertia ixx="0.001" ixy="0" ixz="0" iyy="0.001" iyz="0" izz="0.001"/>
    </inertial>
  </link>
  <joint name="base_to_lidar" type="fixed">
    <parent link="base_link"/>
    <child link="lidar_link"/>
    <origin rpy="0 0 0" xyz="0.11 0.0 0.0"/>
  </joint>
  <!-- Additional laser frame for compatibility -->
  <link name="laser">
    <inertial>
      <mass value="0.001"/>
      <origin rpy="0 0 0" xyz="0 0 0"/>
      <inertia ixx="0.0001" ixy="0" ixz="0" iyy="0.0001" iyz="0" izz="0.0001"/>
    </inertial>
  </link>
  <joint name="lidar_to_laser" type="fixed">
    <parent link="lidar_link"/>
    <child link="laser"/>
    <origin rpy="0 0 0" xyz="0 0 0"/>
  </joint>
  <!-- =====================================================
       IMU SENSOR (GY-91 / MPU6500) - NEW!
       Mounted near Raspberry Pi, away from EMI sources
       
       VERIFIED ORIENTATION from physical testing:
       - IMU Y-axis → Robot FORWARD (X)
       - IMU X-axis → Robot LEFT (Y)
       - IMU Z-axis → Robot UP (Z)
       ===================================================== -->
  <link name="imu_link">
    <visual>
      <geometry>
        <!-- GY-91 board dimensions: approximately 20x15x3mm -->
        <box size="0.020 0.015 0.003"/>
      </geometry>
      <material name="green_imu"/>
      <origin rpy="0 0 0" xyz="0 0 0"/>
    </visual>
    <collision>
      <geometry>
        <box size="0.020 0.015 0.003"/>
      </geometry>
      <origin rpy="0 0 0" xyz="0 0 0"/>
    </collision>
    <inertial>
      <mass value="0.01"/>
      <!-- ~10g for IMU board -->
      <origin rpy="0 0 0" xyz="0 0 0"/>
      <inertia ixx="0.00001" ixy="0" ixz="0" iyy="0.00001" iyz="0" izz="0.00001"/>
    </inertial>
  </link>
  <joint name="base_to_imu" type="fixed">
    <parent link="base_link"/>
    <child link="imu_link"/>
    <!-- 
    Position: Near Raspberry Pi (right side of robot center, 5cm above base)
    Orientation: No rotation needed - IMU axes already mapped in software
    
    Physical IMU orientation:
    - IMU Y-axis points toward robot FRONT (cameras)
    - IMU X-axis points toward robot LEFT  
    - IMU Z-axis points UP
    
    This is handled by axis remapping in imu_node.py, so no RPY rotation needed here.
    -->
    <origin rpy="0 0 0" xyz="0.0 -0.1 0.05"/>
  </joint>
  <!-- =====================================================
       CAMERAS (Microsoft LifeCam Studio) - VERIFIED
       Mounted at top of camera pole
       ===================================================== -->
  <!-- Camera mounting platform -->
  <link name="camera_mount">
    <visual>
      <geometry>
        <box size="0.15 0.10 0.03"/>
      </geometry>
      <material name="metal_gray"/>
      <origin rpy="0 0 0" xyz="0 0 0"/>
    </visual>
    <collision>
      <geometry>
        <box size="0.15 0.10 0.03"/>
      </geometry>
      <origin rpy="0 0 0" xyz="0 0 0"/>
    </collision>
    <inertial>
      <mass value="0.5"/>
      <origin rpy="0 0 0" xyz="0 0 0"/>
      <inertia ixx="0.001" ixy="0" ixz="0" iyy="0.001" iyz="0" izz="0.001"/>
    </inertial>
  </link>
  <joint name="pole_to_camera_mount" type="fixed">
    <parent link="camera_pole"/>
    <child link="camera_mount"/>
    <origin rpy="0 0 0" xyz="0 0 1.219"/>
  </joint>
  <!-- Main Camera Link -->
  <link name="camera_link">
    <visual>
      <geometry>
        <box size="0.05 0.03 0.03"/>
      </geometry>
      <material name="black_rubber"/>
      <origin rpy="0 0 0" xyz="0 0 0"/>
    </visual>
    <collision>
      <geometry>
        <box size="0.05 0.03 0.03"/>
      </geometry>
      <origin rpy="0 0 0" xyz="0 0 0"/>
    </collision>
    <inertial>
      <mass value="0.2"/>
      <origin rpy="0 0 0" xyz="0 0 0"/>
      <inertia ixx="0.0001" ixy="0" ixz="0" iyy="0.0001" iyz="0" izz="0.0001"/>
    </inertial>
  </link>
  <joint name="mount_to_camera_link" type="fixed">
    <parent link="camera_mount"/>
    <child link="camera_link"/>
    <origin rpy="0 0 0" xyz="0 0 0.02"/>
  </joint>
  <!-- Front-facing Camera -->
  <link name="camera_front_link">
    <visual>
      <geometry>
        <box size="0.05 0.03 0.03"/>
      </geometry>
      <material name="black_rubber"/>
      <origin rpy="0 0 0" xyz="0 0 0"/>
    </visual>
    <collision>
      <geometry>
        <box size="0.05 0.03 0.03"/>
      </geometry>
      <origin rpy="0 0 0" xyz="0 0 0"/>
    </collision>
    <inertial>
      <mass value="0.2"/>
      <origin rpy="0 0 0" xyz="0 0 0"/>
      <inertia ixx="0.0001" ixy="0" ixz="0" iyy="0.0001" iyz="0" izz="0.0001"/>
    </inertial>
  </link>
  <joint name="mount_to_camera_front" type="fixed">
    <parent link="camera_mount"/>
    <child link="camera_front_link"/>
    <origin rpy="0 0 0" xyz="0.075 0 0.02"/>
  </joint>
  <!-- Back-facing Camera -->
  <link name="camera_back_link">
    <visual>
      <geometry>
        <box size="0.05 0.03 0.03"/>
      </geometry>
      <material name="black_rubber"/>
      <origin rpy="0 0 0" xyz="0 0 0"/>
    </visual>
    <collision>
      <geometry>
        <box size="0.05 0.03 0.03"/>
      </geometry>
      <origin rpy="0 0 0" xyz="0 0 0"/>
    </collision>
    <inertial>
      <mass value="0.2"/>
      <origin rpy="0 0 0" xyz="0 0 0"/>
      <inertia ixx="0.0001" ixy="0" ixz="0" iyy="0.0001" iyz="0" izz="0.0001"/>
    </inertial>
  </link>
  <joint name="mount_to_camera_back" type="fixed">
    <parent link="camera_mount"/>
    <child link="camera_back_link"/>
    <origin rpy="0 0 3.141592653589793" xyz="-0.075 0 0.02"/>
  </joint>
  <!-- =====================================================
       ROBOT FOOTPRINT FOR NAVIGATION
       Matches robot_params.yaml configuration
       ===================================================== -->
  <!-- 
  Footprint for navigation (from robot_params.yaml):
  footprint: [
    [-0.20, -0.26],   # Back left
    [-0.20,  0.23],   # Back right  
    [ 0.21,  0.23],   # Front right
    [ 0.21, -0.26]    # Front left
  ]
  -->
</robot>

